Data for New York stored successfully.
Data for New York stored successfully.
Data for New York stored successfully.
Data for New York stored successfully.
Data for New York stored successfully.
Data for New York stored successfully.
Data for New York stored successfully.
Data for New York stored successfully.
Data for New York stored successfully.
Error: Unable to fetch data for New York. Status Code: 401
Error: Unable to fetch data for New York. Status Code: 401
Data for New York stored successfully.
Traceback (most recent call last):
  File "C:\Users\ayman\AppData\Local\Programs\Python\Python310\lib\site-packages\urllib3\connection.py", line 199, in _new_conn
    sock = connection.create_connection(
  File "C:\Users\ayman\AppData\Local\Programs\Python\Python310\lib\site-packages\urllib3\util\connection.py", line 60, in create_connection
    for res in socket.getaddrinfo(host, port, family, socket.SOCK_STREAM):
  File "C:\Users\ayman\AppData\Local\Programs\Python\Python310\lib\socket.py", line 955, in getaddrinfo
    for res in _socket.getaddrinfo(host, port, family, type, proto, flags):
socket.gaierror: [Errno 11001] getaddrinfo failed

The above exception was the direct cause of the following exception:

Traceback (most recent call last):
  File "C:\Users\ayman\AppData\Local\Programs\Python\Python310\lib\site-packages\urllib3\connectionpool.py", line 789, in urlopen
    response = self._make_request(
  File "C:\Users\ayman\AppData\Local\Programs\Python\Python310\lib\site-packages\urllib3\connectionpool.py", line 490, in _make_request
    raise new_e
  File "C:\Users\ayman\AppData\Local\Programs\Python\Python310\lib\site-packages\urllib3\connectionpool.py", line 466, in _make_request
    self._validate_conn(conn)
  File "C:\Users\ayman\AppData\Local\Programs\Python\Python310\lib\site-packages\urllib3\connectionpool.py", line 1095, in _validate_conn
    conn.connect()
  File "C:\Users\ayman\AppData\Local\Programs\Python\Python310\lib\site-packages\urllib3\connection.py", line 693, in connect
    self.sock = sock = self._new_conn()
  File "C:\Users\ayman\AppData\Local\Programs\Python\Python310\lib\site-packages\urllib3\connection.py", line 206, in _new_conn
    raise NameResolutionError(self.host, self, e) from e
urllib3.exceptions.NameResolutionError: <urllib3.connection.HTTPSConnection object at 0x000002CC29D99300>: Failed to resolve 'api.openweathermap.org' ([Errno 11001] getaddrinfo failed)

The above exception was the direct cause of the following exception:

Traceback (most recent call last):
  File "C:\Users\ayman\AppData\Local\Programs\Python\Python310\lib\site-packages\requests\adapters.py", line 667, in send
    resp = conn.urlopen(
  File "C:\Users\ayman\AppData\Local\Programs\Python\Python310\lib\site-packages\urllib3\connectionpool.py", line 843, in urlopen
    retries = retries.increment(
  File "C:\Users\ayman\AppData\Local\Programs\Python\Python310\lib\site-packages\urllib3\util\retry.py", line 519, in increment
    raise MaxRetryError(_pool, url, reason) from reason  # type: ignore[arg-type]
urllib3.exceptions.MaxRetryError: HTTPSConnectionPool(host='api.openweathermap.org', port=443): Max retries exceeded with url: /data/2.5/weather?q=New+York&appid=c1cb2d3577d444498b1e328a15ed5716&units=metric (Caused by NameResolutionError("<urllib3.connection.HTTPSConnection object at 0x000002CC29D99300>: Failed to resolve 'api.openweathermap.org' ([Errno 11001] getaddrinfo failed)"))

During handling of the above exception, another exception occurred:

Traceback (most recent call last):
  File "C:\Users\ayman\Desktop\Projects\ETL_Pipeline\extract2.py", line 105, in <module>
    weather_data = fetch_weather_data(CITY)
  File "C:\Users\ayman\Desktop\Projects\ETL_Pipeline\extract2.py", line 18, in fetch_weather_data
    response = requests.get(BASE_URL, params=params)
  File "C:\Users\ayman\AppData\Local\Programs\Python\Python310\lib\site-packages\requests\api.py", line 73, in get
    return request("get", url, params=params, **kwargs)
  File "C:\Users\ayman\AppData\Local\Programs\Python\Python310\lib\site-packages\requests\api.py", line 59, in request
    return session.request(method=method, url=url, **kwargs)
  File "C:\Users\ayman\AppData\Local\Programs\Python\Python310\lib\site-packages\requests\sessions.py", line 589, in request
    resp = self.send(prep, **send_kwargs)
  File "C:\Users\ayman\AppData\Local\Programs\Python\Python310\lib\site-packages\requests\sessions.py", line 703, in send
    r = adapter.send(request, **kwargs)
  File "C:\Users\ayman\AppData\Local\Programs\Python\Python310\lib\site-packages\requests\adapters.py", line 700, in send
    raise ConnectionError(e, request=request)
requests.exceptions.ConnectionError: HTTPSConnectionPool(host='api.openweathermap.org', port=443): Max retries exceeded with url: /data/2.5/weather?q=New+York&appid=c1cb2d3577d444498b1e328a15ed5716&units=metric (Caused by NameResolutionError("<urllib3.connection.HTTPSConnection object at 0x000002CC29D99300>: Failed to resolve 'api.openweathermap.org' ([Errno 11001] getaddrinfo failed)"))
Data for New York stored successfully.
Data for New York stored successfully.
Data for New York stored successfully.
Data for New York stored successfully.
Data for New York stored successfully.
Data for New York stored successfully.
Data for New York stored successfully.
Data for New York stored successfully.
Data for New York stored successfully.
Data for New York stored successfully.
Data for New York stored successfully.
Data for New York stored successfully.
Data for New York stored successfully.
